<?xml version="1.0" ?>
<robot name="bug_robot" xmlns:xacro="http://www.ros.org/wiki/xacro">

<xacro:include filename="$(find bug_robot_description)/urdf/materials.xacro" />
<xacro:include filename="$(find bug_robot_description)/urdf/bug_robot.trans" />
<xacro:include filename="$(find bug_robot_description)/urdf/bug_robot.gazebo" />
<link name="base_link">
  <inertial>
    <origin rpy="0 0 0" xyz="-0.005896999765536513 -1.4328462557639305e-17 0.03848205087229334"/>
    <mass value="1.3456634024776193"/>
    <inertia ixx="0.002939" ixy="-0.0" ixz="0.000357" iyy="0.004824" iyz="-0.0" izz="0.00646"/>
  </inertial>
  <visual>
    <origin rpy="0 0 0" xyz="0 0 0"/>
    <geometry>
      <mesh filename="package://bug_robot_description/meshes/base_link.stl" scale="0.001 0.001 0.001"/>
    </geometry>
    <material name="orange"/>
  </visual>
  <collision>
    <origin rpy="0 0 0" xyz="0 0 0"/>
    <geometry>
      <mesh filename="package://bug_robot_description/meshes/base_link.stl" scale="0.001 0.001 0.001"/>
    </geometry>
  </collision>
</link>

<link name="r_wheel_1">
  <inertial>
    <origin rpy="0 0 0" xyz="0.0 -0.012499999999999997 0.0"/>
    <mass value="0.07518292500997298"/>
    <inertia ixx="2.3e-05" ixy="-0.0" ixz="0.0" iyy="3.9e-05" iyz="0.0" izz="2.3e-05"/>
  </inertial>
  <visual>
    <origin rpy="0 0 0" xyz="0.065 0.085 -0.0325"/>
    <geometry>
      <mesh filename="package://bug_robot_description/meshes/r_wheel_1.stl" scale="0.001 0.001 0.001"/>
    </geometry>
    <material name="black"/>
  </visual>
  <collision>
    <origin rpy="0 0 0" xyz="0.065 0.085 -0.0325"/>
    <geometry>
      <mesh filename="package://bug_robot_description/meshes/r_wheel_1.stl" scale="0.001 0.001 0.001"/>
    </geometry>
  </collision>
</link>

<link name="l_wheel_1">
  <inertial>
    <origin rpy="0 0 0" xyz="0.0 0.012499999999999997 0.0"/>
    <mass value="0.07518292500997296"/>
    <inertia ixx="2.3e-05" ixy="0.0" ixz="0.0" iyy="3.9e-05" iyz="0.0" izz="2.3e-05"/>
  </inertial>
  <visual>
    <origin rpy="0 0 0" xyz="0.065 -0.085 -0.0325"/>
    <geometry>
      <mesh filename="package://bug_robot_description/meshes/l_wheel_1.stl" scale="0.001 0.001 0.001"/>
    </geometry>
    <material name="black"/>
  </visual>
  <collision>
    <origin rpy="0 0 0" xyz="0.065 -0.085 -0.0325"/>
    <geometry>
      <mesh filename="package://bug_robot_description/meshes/l_wheel_1.stl" scale="0.001 0.001 0.001"/>
    </geometry>
  </collision>
</link>

<link name="l298n_1">
  <inertial>
    <origin rpy="0 0 0" xyz="0.014163770913449671 -0.033295829595900696 0.007190920056232196"/>
    <mass value="0.06824067923307132"/>
    <inertia ixx="1.4e-05" ixy="-1e-06" ixz="-0.0" iyy="1e-05" iyz="-2e-06" izz="1.9e-05"/>
  </inertial>
  <visual>
    <origin rpy="0 0 0" xyz="-0.0 -0.0 -0.0525"/>
    <geometry>
      <mesh filename="package://bug_robot_description/meshes/l298n_1.stl" scale="0.001 0.001 0.001"/>
    </geometry>
    <material name="red"/>
  </visual>
  <collision>
    <origin rpy="0 0 0" xyz="-0.0 -0.0 -0.0525"/>
    <geometry>
      <mesh filename="package://bug_robot_description/meshes/l298n_1.stl" scale="0.001 0.001 0.001"/>
    </geometry>
  </collision>
</link>

<link name="rasp_pi_1">
  <inertial>
    <origin rpy="0 0 0" xyz="0.04075400836508636 0.014965472519732783 0.004888830680916854"/>
    <mass value="0.13472167579144437"/>
    <inertia ixx="8.3e-05" ixy="0.0" ixz="-0.0" iyy="4.1e-05" iyz="-9e-06" izz="0.000118"/>
  </inertial>
  <visual>
    <origin rpy="0 0 0" xyz="0.095 -0.0 -0.0525"/>
    <geometry>
      <mesh filename="package://bug_robot_description/meshes/rasp_pi_1.stl" scale="0.001 0.001 0.001"/>
    </geometry>
    <material name="green"/>
  </visual>
  <collision>
    <origin rpy="0 0 0" xyz="0.095 -0.0 -0.0525"/>
    <geometry>
      <mesh filename="package://bug_robot_description/meshes/rasp_pi_1.stl" scale="0.001 0.001 0.001"/>
    </geometry>
  </collision>
</link>

<link name="arduino_1">
  <inertial>
    <origin rpy="0 0 0" xyz="0.019593941718230427 -0.039758296473014224 0.0024136106182991654"/>
    <mass value="0.07205091114025565"/>
    <inertia ixx="3.1e-05" ixy="0.0" ixz="0.0" iyy="2e-05" iyz="-1e-06" izz="5e-05"/>
  </inertial>
  <visual>
    <origin rpy="0 0 0" xyz="0.005 -0.07 -0.0525"/>
    <geometry>
      <mesh filename="package://bug_robot_description/meshes/arduino_1.stl" scale="0.001 0.001 0.001"/>
    </geometry>
    <material name="blue"/>
  </visual>
  <collision>
    <origin rpy="0 0 0" xyz="0.005 -0.07 -0.0525"/>
    <geometry>
      <mesh filename="package://bug_robot_description/meshes/arduino_1.stl" scale="0.001 0.001 0.001"/>
    </geometry>
  </collision>
</link>

<link name="lidar_1">
  <inertial>
    <origin rpy="0 0 0" xyz="-6.938893903907228e-18 4.92348903071601e-18 0.007500000000000034"/>
    <mass value="0.07966293571340317"/>
    <inertia ixx="2.6e-05" ixy="0.0" ixz="0.0" iyy="2.6e-05" iyz="-0.0" izz="4.9e-05"/>
  </inertial>
  <visual>
    <origin rpy="0 0 0" xyz="0.05 -0.0 -0.1125"/>
    <geometry>
      <mesh filename="package://bug_robot_description/meshes/lidar_1.stl" scale="0.001 0.001 0.001"/>
    </geometry>
    <material name="blue"/>
  </visual>
  <collision>
    <origin rpy="0 0 0" xyz="0.05 -0.0 -0.1125"/>
    <geometry>
      <mesh filename="package://bug_robot_description/meshes/lidar_1.stl" scale="0.001 0.001 0.001"/>
    </geometry>
  </collision>
</link>

<link name="camera_1">
  <inertial>
    <origin rpy="0 0 0" xyz="-0.020000000000000004 4.876485264250459e-18 0.014623949743276375"/>
    <mass value="0.04021539786195391"/>
    <inertia ixx="1.1e-05" ixy="0.0" ixz="0.0" iyy="4e-06" iyz="0.0" izz="9e-06"/>
  </inertial>
  <visual>
    <origin rpy="0 0 0" xyz="-0.095 -0.0 -0.0525"/>
    <geometry>
      <mesh filename="package://bug_robot_description/meshes/camera_1.stl" scale="0.001 0.001 0.001"/>
    </geometry>
    <material name="red"/>
  </visual>
  <collision>
    <origin rpy="0 0 0" xyz="-0.095 -0.0 -0.0525"/>
    <geometry>
      <mesh filename="package://bug_robot_description/meshes/camera_1.stl" scale="0.001 0.001 0.001"/>
    </geometry>
  </collision>
</link>

<link name="r_caster_1">
  <inertial>
    <origin rpy="0 0 0" xyz="-0.020000000000000004 -0.045 -0.004886363636363636"/>
    <mass value="0.0026782077371852973"/>
    <inertia ixx="0.0" ixy="0.0" ixz="-0.0" iyy="0.0" iyz="0.0" izz="0.0"/>
  </inertial>
  <visual>
    <origin rpy="0 0 0" xyz="-0.095 -0.0 -0.0125"/>
    <geometry>
      <mesh filename="package://bug_robot_description/meshes/r_caster_1.stl" scale="0.001 0.001 0.001"/>
    </geometry>
    <material name="black"/>
  </visual>
  <collision>
    <origin rpy="0 0 0" xyz="-0.095 -0.0 -0.0125"/>
    <geometry>
      <mesh filename="package://bug_robot_description/meshes/r_caster_1.stl" scale="0.001 0.001 0.001"/>
    </geometry>
  </collision>
</link>

<link name="l_caster_1">
  <inertial>
    <origin rpy="0 0 0" xyz="-0.020000000000000004 0.045 -0.004886363636363636"/>
    <mass value="0.0026782077371852973"/>
    <inertia ixx="0.0" ixy="0.0" ixz="-0.0" iyy="0.0" iyz="-0.0" izz="0.0"/>
  </inertial>
  <visual>
    <origin rpy="0 0 0" xyz="-0.095 -0.0 -0.0125"/>
    <geometry>
      <mesh filename="package://bug_robot_description/meshes/l_caster_1.stl" scale="0.001 0.001 0.001"/>
    </geometry>
    <material name="black"/>
  </visual>
  <collision>
    <origin rpy="0 0 0" xyz="-0.095 -0.0 -0.0125"/>
    <geometry>
      <mesh filename="package://bug_robot_description/meshes/l_caster_1.stl" scale="0.001 0.001 0.001"/>
    </geometry>
  </collision>
</link>

<joint name="Rev1" type="continuous">
  <origin rpy="0 0 0" xyz="-0.065 -0.085 0.0325"/>
  <parent link="base_link"/>
  <child link="r_wheel_1"/>
  <axis xyz="0.0 1.0 0.0"/>
</joint>

<joint name="Rev2" type="continuous">
  <origin rpy="0 0 0" xyz="-0.065 0.085 0.0325"/>
  <parent link="base_link"/>
  <child link="l_wheel_1"/>
  <axis xyz="0.0 1.0 0.0"/>
</joint>

<joint name="Rigid3" type="fixed">
  <origin rpy="0 0 0" xyz="0.0 0.0 0.0525"/>
  <parent link="base_link"/>
  <child link="l298n_1"/>
</joint>

<joint name="Rigid4" type="fixed">
  <origin rpy="0 0 0" xyz="-0.095 0.0 0.0525"/>
  <parent link="base_link"/>
  <child link="rasp_pi_1"/>
</joint>

<joint name="Rigid5" type="fixed">
  <origin rpy="0 0 0" xyz="-0.005 0.07 0.0525"/>
  <parent link="base_link"/>
  <child link="arduino_1"/>
</joint>

<joint name="Rigid6" type="fixed">
  <origin rpy="0 0 0" xyz="-0.05 0.0 0.1125"/>
  <parent link="base_link"/>
  <child link="lidar_1"/>
</joint>

<joint name="Rigid7" type="fixed">
  <origin rpy="0 0 0" xyz="0.095 0.0 0.0525"/>
  <parent link="base_link"/>
  <child link="camera_1"/>
</joint>

<joint name="Rigid8" type="fixed">
  <origin rpy="0 0 0" xyz="0.095 0.0 0.0125"/>
  <parent link="base_link"/>
  <child link="r_caster_1"/>
</joint>

<joint name="Rigid9" type="fixed">
  <origin rpy="0 0 0" xyz="0.095 0.0 0.0125"/>
  <parent link="base_link"/>
  <child link="l_caster_1"/>
</joint>

</robot>
